Workbook

Sheet Rel 2026 08
A1: Elegível | B1: Elegível2 | C1: Responsável | D1: Agência | E1: chave_loja | F1: nome_loja | G1: ag_pacb | H1: dt_inst_tablet | I1: uf | J1: municipio | K1: dt_clube | L1: dt_certificacao | M1: ger_regional | N1: data_ult_transacao | O1: qtd_TrxContabil | P1: qtd_contas | Q1: qtd_contas_com_deposito | R1: qtd_cesta_serv | S1: QTD_CARTAO_EMITIDO | T1: vlr_lime | U1: vlr_consignado_total | V1: vlr_consignado_inss | W1: vlr_consignado_pub | X1: vlr_consignado_priv | Y1: VLR_CREDITO_PARCEL | Z1: QTD_CONTAS_PJ | AA1: qtd_microsseguro | AB1: QTD_SUPER_PROTEGIDO | AC1: QTD_MICRO_VIVAVIDA | AD1: QTD_PLANO_ODONTO | AE1: QTD_SEG_RESIDENCIAL | AF1: QTD_SEG_CARTAO_DEB | AG1: VLR_EXP_SORTE | AH1: REFERENCIA | AI1: BLOQUEADO | AJ1: DT_BLOQUEADO | AK1: Status | AL1: Pontuação | AM1: Zero | AN1: Pontuação2
A2: =IF(Rel_2026[[#This Row],[Zero]]=0,"Zero",IF(Rel_2026[[#This Row],[Pontuação]]>=10,"Sim",IF(Rel_2026[[#This Row],[Pontuação]]>=5,"Próximo","Não"))) -> Não | B2: =IF(Rel_2026[[#This Row],[Zero]]=0,"Zero",IF(Rel_2026[[#This Row],[Pontuação2]]>=10,"Sim",IF(Rel_2026[[#This Row],[Pontuação2]]>=5,"Próximo","Não"))) -> Não | C2: =IFERROR(VLOOKUP(Rel_2026[[#This Row],[chave_loja]],Responsavel!A:B,2,FALSE),"EUCLIDES") -> JUNIOR | D2: =LEFT(Rel_2026[[#This Row],[ag_pacb]],4) -> 1351 | E2: 408134 | F2: Valeria Auto Pecas | G2: 1351/333 | H2: 45793 | I2: CE | J2: AMONTADA | K2: 45623 | L2: 45817 | M2: FORTALEZA OESTE | N2: 46248 | O2: 141 | P2: 0 | Q2: 0 | R2: 0 | S2: 0 | T2: 0 | U2: 0 | V2: 0 | W2: 0 | X2: 0 | Y2: 0 | Z2: 0 | AA2: 0 | AB2: 0 | AC2: 0 | AD2: 0 | AE2: 0 | AF2: 0 | AG2: 0 | AH2: Nao | AI2: Desbloqueado | AK2: TREINADO | AL2: =IF(Rel_2026[[#This Row],[qtd_contas_com_deposito]]>0,7*Rel_2026[[#This Row],[qtd_contas_com_deposito]])+IF((Rel_2026[[#This Row],[qtd_contas]]-Rel_2026[[#This Row],[qtd_contas_com_deposito]])>0,(Rel_2026[[#This Row],[qtd_contas]]-Rel_2026[[#This Row],[qtd_contas_com_deposito]])*3)+IF(Rel_2026[[#This Row],[qtd_cesta_serv]]>0,0*Rel_2026[[#This Row],[qtd_cesta_serv]])+IF(Rel_2026[[#This Row],[QTD_CARTAO_EMITIDO]]>0,0*Rel_2026[[#This Row],[QTD_CARTAO_EMITIDO]])+IF(Rel_2026[[#This Row],[QTD_SUPER_PROTEGIDO]]>0,0*Rel_2026[[#This Row],[QTD_SUPER_PROTEGIDO]])+IF(Rel_2026[[#This Row],[QTD_CONTAS_PJ]]>0,0*Rel_2026[[#This Row],[QTD_CONTAS_PJ]])+IF(Rel_2026[[#This Row],[QTD_MICRO_VIVAVIDA]]>0,1*Rel_2026[[#This Row],[QTD_MICRO_VIVAVIDA]])+IF(Rel_2026[[#This Row],[qtd_microsseguro]]>0,1*Rel_2026[[#This Row],[qtd_microsseguro]])+IF(Rel_2026[[#This Row],[QTD_SEG_RESIDENCIAL]]>0,1*Rel_2026[[#This Row],[QTD_SEG_RESIDENCIAL]])+IF(Rel_2026[[#This Row],[QTD_PLANO_ODONTO]]>0,1*Rel_2026[[#This Row],[QTD_PLANO_ODONTO]])+IF(Rel_2026[[#This Row],[vlr_lime]]>0,1*ROUND(Rel_2026[[#This Row],[vlr_lime]]/100,0))+ROUND(IF(Rel_2026[[#This Row],[VLR_CREDITO_PARCEL]]>500,1*Rel_2026[[#This Row],[VLR_CREDITO_PARCEL]]/500),0)+ROUND(Rel_2026[[#This Row],[vlr_consignado_total]]/1000,0)+ROUND(Rel_2026[[#This Row],[VLR_EXP_SORTE]]/50,0) -> 0 | AM2: =SUM(Rel_2026[[#This Row],[qtd_TrxContabil]:[VLR_EXP_SORTE]]) -> 141 | AN2: =IF(Rel_2026[[#This Row],[qtd_contas_com_deposito]]>0,7*Rel_2026[[#This Row],[qtd_contas_com_deposito]])+IF((Rel_2026[[#This Row],[qtd_contas]]-Rel_2026[[#This Row],[qtd_contas_com_deposito]])>0,(Rel_2026[[#This Row],[qtd_contas]]-Rel_2026[[#This Row],[qtd_contas_com_deposito]])*3)+IF(Rel_2026[[#This Row],[qtd_cesta_serv]]>0,3*Rel_2026[[#This Row],[qtd_cesta_serv]])+IF(Rel_2026[[#This Row],[QTD_CARTAO_EMITIDO]]>0,0*Rel_2026[[#This Row],[QTD_CARTAO_EMITIDO]])+IF(Rel_2026[[#This Row],[QTD_SUPER_PROTEGIDO]]>0,0*Rel_2026[[#This Row],[QTD_SUPER_PROTEGIDO]])+IF(Rel_2026[[#This Row],[QTD_CONTAS_PJ]]>0,0*Rel_2026[[#This Row],[QTD_CONTAS_PJ]])+IF(Rel_2026[[#This Row],[QTD_MICRO_VIVAVIDA]]>0,1*Rel_2026[[#This Row],[QTD_MICRO_VIVAVIDA]])+IF(Rel_2026[[#This Row],[qtd_microsseguro]]>0,1*Rel_2026[[#This Row],[qtd_microsseguro]])+IF(Rel_2026[[#This Row],[QTD_SEG_RESIDENCIAL]]>0,1*Rel_2026[[#This Row],[QTD_SEG_RESIDENCIAL]])+IF(Rel_2026[[#This Row],[QTD_PLANO_ODONTO]]>0,1*Rel_2026[[#This Row],[QTD_PLANO_ODONTO]])+IF(Rel_2026[[#This Row],[vlr_lime]]>0,1*ROUND(Rel_2026[[#This Row],[vlr_lime]]/100,0))+ROUND(IF(Rel_2026[[#This Row],[VLR_CREDITO_PARCEL]]>500,1*Rel_2026[[#This Row],[VLR_CREDITO_PARCEL]]/500),0)+ROUND(Rel_2026[[#This Row],[vlr_consignado_total]]/1000,0)+ROUND(Rel_2026[[#This Row],[VLR_EXP_SORTE]]/50,0) -> 0
A3: =IF(Rel_2026[[#This Row],[Zero]]=0,"Zero",IF(Rel_2026[[#This Row],[Pontuação]]>=10,"Sim",IF(Rel_2026[[#This Row],[Pontuação]]>=5,"Próximo","Não"))) -> Não | B3: =IF(Rel_2026[[#This Row],[Zero]]=0,"Zero",IF(Rel_2026[[#This Row],[Pontuação2]]>=10,"Sim",IF(Rel_2026[[#This Row],[Pontuação2]]>=5,"Próximo","Não"))) -> Não | C3: =IFERROR(VLOOKUP(Rel_2026[[#This Row],[chave_loja]],Responsavel!A:B,2,FALSE),"EUCLIDES") -> ROSSY | D3: =LEFT(Rel_2026[[#This Row],[ag_pacb]],4) -> 0854 | E3: 423538 | F3: Do Povo Casa De Construções | G3: 0854/193 | H3: 46134 | I3: MA | J3: TIMON | K3: 46125 | L3: 46149 | M3: TERESINA | N3: 46254 | O3: 163 | P3: 0 | Q3: 0 | R3: 0 | S3: 0 | T3: 0 | U3: 0 | V3: 0 | W3: 0 | X3: 0 | Y3: 0 | Z3: 0 | AA3: 0 | AB3: 0 | AC3: 0 | AD3: 0 | AE3: 0 | AF3: 0 | AG3: 0 | AH3: Nao | AI3: Desbloqueado | AK3: TREINADO | AL3: =IF(Rel_2026[[#This Row],[qtd_contas_com_deposito]]>0,7*Rel_2026[[#This Row],[qtd_contas_com_deposito]])+IF((Rel_2026[[#This Row],[qtd_contas]]-Rel_2026[[#This Row],[qtd_contas_com_deposito]])>0,(Rel_2026[[#This Row],[qtd_contas]]-Rel_2026[[#This Row],[qtd_contas_com_deposito]])*3)+IF(Rel_2026[[#This Row],[qtd_cesta_serv]]>0,0*Rel_2026[[#This Row],[qtd_cesta_serv]])+IF(Rel_2026[[#This Row],[QTD_CARTAO_EMITIDO]]>0,0*Rel_2026[[#This Row],[QTD_CARTAO_EMITIDO]])+IF(Rel_2026[[#This Row],[QTD_SUPER_PROTEGIDO]]>0,0*Rel_2026[[#This Row],[QTD_SUPER_PROTEGIDO]])+IF(Rel_2026[[#This Row],[QTD_CONTAS_PJ]]>0,0*Rel_2026[[#This Row],[QTD_CONTAS_PJ]])+IF(Rel_2026[[#This Row],[QTD_MICRO_VIVAVIDA]]>0,1*Rel_2026[[#This Row],[QTD_MICRO_VIVAVIDA]])+IF(Rel_2026[[#This Row],[qtd_microsseguro]]>0,1*Rel_2026[[#This Row],[qtd_microsseguro]])+IF(Rel_2026[[#This Row],[QTD_SEG_RESIDENCIAL]]>0,1*Rel_2026[[#This Row],[QTD_SEG_RESIDENCIAL]])+IF(Rel_2026[[#This Row],[QTD_PLANO_ODONTO]]>0,1*Rel_2026[[#This Row],[QTD_PLANO_ODONTO]])+IF(Rel_2026[[#This Row],[vlr_lime]]>0,1*ROUND(Rel_2026[[#This Row],[vlr_lime]]/100,0))+ROUND(IF(Rel_2026[[#This Row],[VLR_CREDITO_PARCEL]]>500,1*Rel_2026[[#This Row],[VLR_CREDITO_PARCEL]]/500),0)+ROUND(Rel_2026[[#This Row],[vlr_consignado_total]]/1000,0)+ROUND(Rel_2026[[#This Row],[VLR_EXP_SORTE]]/50,0) -> 0 | AM3: =SUM(Rel_2026[[#This Row],[qtd_TrxContabil]:[VLR_EXP_SORTE]]) -> 163 | AN3: =IF(Rel_2026[[#This Row],[qtd_contas_com_deposito]]>0,7*Rel_2026[[#This Row],[qtd_contas_com_deposito]])+IF((Rel_2026[[#This Row],[qtd_contas]]-Rel_2026[[#This Row],[qtd_contas_com_deposito]])>0,(Rel_2026[[#This Row],[qtd_contas]]-Rel_2026[[#This Row],[qtd_contas_com_deposito]])*3)+IF(Rel_2026[[#This Row],[qtd_cesta_serv]]>0,3*Rel_2026[[#This Row],[qtd_cesta_serv]])+IF(Rel_2026[[#This Row],[QTD_CARTAO_EMITIDO]]>0,0*Rel_2026[[#This Row],[QTD_CARTAO_EMITIDO]])+IF(Rel_2026[[#This Row],[QTD_SUPER_PROTEGIDO]]>0,0*Rel_2026[[#This Row],[QTD_SUPER_PROTEGIDO]])+IF(Rel_2026[[#This Row],[QTD_CONTAS_PJ]]>0,0*Rel_2026[[#This Row],[QTD_CONTAS_PJ]])+IF(Rel_2026[[#This Row],[QTD_MICRO_VIVAVIDA]]>0,1*Rel_2026[[#This Row],[QTD_MICRO_VIVAVIDA]])+IF(Rel_2026[[#This Row],[qtd_microsseguro]]>0,1*Rel_2026[[#This Row],[qtd_microsseguro]])+IF(Rel_2026[[#This Row],[QTD_SEG_RESIDENCIAL]]>0,1*Rel_2026[[#This Row],[QTD_SEG_RESIDENCIAL]])+IF(Rel_2026[[#This Row],[QTD_PLANO_ODONTO]]>0,1*Rel_2026[[#This Row],[QTD_PLANO_ODONTO]])+IF(Rel_2026[[#This Row],[vlr_lime]]>0,1*ROUND(Rel_2026[[#This Row],[vlr_lime]]/100,0))+ROUND(IF(Rel_2026[[#This Row],[VLR_CREDITO_PARCEL]]>500,1*Rel_2026[[#This Row],[VLR_CREDITO_PARCEL]]/500),0)+ROUND(Rel_2026[[#This Row],[vlr_consignado_total]]/1000,0)+ROUND(Rel_2026[[#This Row],[VLR_EXP_SORTE]]/50,0) -> 0
A4: =IF(Rel_2026[[#This Row],[Zero]]=0,"Zero",IF(Rel_2026[[#This Row],[Pontuação]]>=10,"Sim",IF(Rel_2026[[#This Row],[Pontuação]]>=5,"Próximo","Não"))) -> Sim | B4: =IF(Rel_2026[[#This Row],[Zero]]=0,"Zero",IF(Rel_2026[[#This Row],[Pontuação2]]>=10,"Sim",IF(Rel_2026[[#This Row],[Pontuação2]]>=5,"Próximo","Não"))) -> Sim | C4: =IFERROR(VLOOKUP(Rel_2026[[#This Row],[chave_loja]],Responsavel!A:B,2,FALSE),"EUCLIDES") -> CÉLIO | D4: =LEFT(Rel_2026[[#This Row],[ag_pacb]],4) -> 0625 | E4: 136478 | F4: TURQUESA ACESSORIOS | G4: 0625/089 | H4: 45120 | I4: CE | J4: FORTALEZA | K4: 45306 | L4: 45495 | M4: FORTALEZA OESTE | N4: 46254 | O4: 14 | P4: 21 | Q4: 0 | R4: 14 | S4: 3 | T4: 0 | U4: 0 | V4: 0 | W4: 0 | X4: 0 | Y4: 0 | Z4: 0 | AA4: 0 | AB4: 4 | AC4: 0 | AD4: 0 | AE4: 0 | AF4: 15 | AG4: 0 | AH4: Nao | AI4: Desbloqueado | AK4: TREINADO | AL4: =IF(Rel_2026[[#This Row],[qtd_contas_com_deposito]]>0,7*Rel_2026[[#This Row],[qtd_contas_com_deposito]])+IF((Rel_2026[[#This Row],[qtd_contas]]-Rel_2026[[#This Row],[qtd_contas_com_deposito]])>0,(Rel_2026[[#This Row],[qtd_contas]]-Rel_2026[[#This Row],[qtd_contas_com_deposito]])*3)+IF(Rel_2026[[#This Row],[qtd_cesta_serv]]>0,0*Rel_2026[[#This Row],[qtd_cesta_serv]])+IF(Rel_2026[[#This Row],[QTD_CARTAO_EMITIDO]]>0,0*Rel_2026[[#This Row],[QTD_CARTAO_EMITIDO]])+IF(Rel_2026[[#This Row],[QTD_SUPER_PROTEGIDO]]>0,0*Rel_2026[[#This Row],[QTD_SUPER_PROTEGIDO]])+IF(Rel_2026[[#This Row],[QTD_CONTAS_PJ]]>0,0*Rel_2026[[#This Row],[QTD_CONTAS_PJ]])+IF(Rel_2026[[#This Row],[QTD_MICRO_VIVAVIDA]]>0,1*Rel_2026[[#This Row],[QTD_MICRO_VIVAVIDA]])+IF(Rel_2026[[#This Row],[qtd_microsseguro]]>0,1*Rel_2026[[#This Row],[qtd_microsseguro]])+IF(Rel_2026[[#This Row],[QTD_SEG_RESIDENCIAL]]>0,1*Rel_2026[[#This Row],[QTD_SEG_RESIDENCIAL]])+IF(Rel_2026[[#This Row],[QTD_PLANO_ODONTO]]>0,1*Rel_2026[[#This Row],[QTD_PLANO_ODONTO]])+IF(Rel_2026[[#This Row],[vlr_lime]]>0,1*ROUND(Rel_2026[[#This Row],[vlr_lime]]/100,0))+ROUND(IF(Rel_2026[[#This Row],[VLR_CREDITO_PARCEL]]>500,1*Rel_2026[[#This Row],[VLR_CREDITO_PARCEL]]/500),0)+ROUND(Rel_2026[[#This Row],[vlr_consignado_total]]/1000,0)+ROUND(Rel_2026[[#This Row],[VLR_EXP_SORTE]]/50,0) -> 63 | AM4: =SUM(Rel_2026[[#This Row],[qtd_TrxContabil]:[VLR_EXP_SORTE]]) -> 71 | AN4: =IF(Rel_2026[[#This Row],[qtd_contas_com_deposito]]>0,7*Rel_2026[[#This Row],[qtd_contas_com_deposito]])+IF((Rel_2026[[#This Row],[qtd_contas]]-Rel_2026[[#This Row],[qtd_contas_com_deposito]])>0,(Rel_2026[[#This Row],[qtd_contas]]-Rel_2026[[#This Row],[qtd_contas_com_deposito]])*3)+IF(Rel_2026[[#This Row],[qtd_cesta_serv]]>0,3*Rel_2026[[#This Row],[qtd_cesta_serv]])+IF(Rel_2026[[#This Row],[QTD_CARTAO_EMITIDO]]>0,0*Rel_2026[[#This Row],[QTD_CARTAO_EMITIDO]])+IF(Rel_2026[[#This Row],[QTD_SUPER_PROTEGIDO]]>0,0*Rel_2026[[#This Row],[QTD_SUPER_PROTEGIDO]])+IF(Rel_2026[[#This Row],[QTD_CONTAS_PJ]]>0,0*Rel_2026[[#This Row],[QTD_CONTAS_PJ]])+IF(Rel_2026[[#This Row],[QTD_MICRO_VIVAVIDA]]>0,1*Rel_2026[[#This Row],[QTD_MICRO_VIVAVIDA]])+IF(Rel_2026[[#This Row],[qtd_microsseguro]]>0,1*Rel_2026[[#This Row],[qtd_microsseguro]])+IF(Rel_2026[[#This Row],[QTD_SEG_RESIDENCIAL]]>0,1*Rel_2026[[#This Row],[QTD_SEG_RESIDENCIAL]])+IF(Rel_2026[[#This Row],[QTD_PLANO_ODONTO]]>0,1*Rel_2026[[#This Row],[QTD_PLANO_ODONTO]])+IF(Rel_2026[[#This Row],[vlr_lime]]>0,1*ROUND(Rel_2026[[#This Row],[vlr_lime]]/100,0))+ROUND(IF(Rel_2026[[#This Row],[VLR_CREDITO_PARCEL]]>500,1*Rel_2026[[#This Row],[VLR_CREDITO_PARCEL]]/500),0)+ROUND(Rel_2026[[#This Row],[vlr_consignado_total]]/1000,0)+ROUND(Rel_2026[[#This Row],[VLR_EXP_SORTE]]/50,0) -> 105
A5: =IF(Rel_2026[[#This Row],[Zero]]=0,"Zero",IF(Rel_2026[[#This Row],[Pontuação]]>=10,"Sim",IF(Rel_2026[[#This Row],[Pontuação]]>=5,"Próximo","Não"))) -> Sim | B5: =IF(Rel_2026[[#This Row],[Zero]]=0,"Zero",IF(Rel_2026[[#This Row],[Pontuação2]]>=10,"Sim",IF(Rel_2026[[#This Row],[Pontuação2]]>=5,"Próximo","Não"))) -> Sim | C5: =IFERROR(VLOOKUP(Rel_2026[[#This Row],[chave_loja]],Responsavel!A:B,2,FALSE),"EUCLIDES") -> WASTHSON | D5: =LEFT(Rel_2026[[#This Row],[ag_pacb]],4) -> 0702 | E5: 180964 | F5: MERCADINHO NSA SENHORA DE FATIMA | G5: 0702/131 | H5: 45128 | I5: CE | J5: CARIRE | K5: 43795 | L5: 45597 | M5: FORTALEZA OESTE | N5: 46254 | O5: 556 | P5: 2 | Q5: 2 | R5: 1 | S5: 0 | T5: 0 | U5: 0 | V5: 0 | W5: 0 | X5: 0 | Y5: 0 | Z5: 0 | AA5: 0 | AB5: 0 | AC5: 0 | AD5: 0 | AE5: 0 | AF5: 0 | AG5: 0 | AH5: Nao | AI5: Desbloqueado | AK5: TREINADO | AL5: =IF(Rel_2026[[#This Row],[qtd_contas_com_deposito]]>0,7*Rel_2026[[#This Row],[qtd_contas_com_deposito]])+IF((Rel_2026[[#This Row],[qtd_contas]]-Rel_2026[[#This Row],[qtd_contas_com_deposito]])>0,(Rel_2026[[#This Row],[qtd_contas]]-Rel_2026[[#This Row],[qtd_contas_com_deposito]])*3)+IF(Rel_2026[[#This Row],[qtd_cesta_serv]]>0,0*Rel_2026[[#This Row],[qtd_cesta_serv]])+IF(Rel_2026[[#This Row],[QTD_CARTAO_EMITIDO]]>0,0*Rel_2026[[#This Row],[QTD_CARTAO_EMITIDO]])+IF(Rel_2026[[#This Row],[QTD_SUPER_PROTEGIDO]]>0,0*Rel_2026[[#This Row],[QTD_SUPER_PROTEGIDO]])+IF(Rel_2026[[#This Row],[QTD_CONTAS_PJ]]>0,0*Rel_2026[[#This Row],[QTD_CONTAS_PJ]])+IF(Rel_2026[[#This Row],[QTD_MICRO_VIVAVIDA]]>0,1*Rel_2026[[#This Row],[QTD_MICRO_VIVAVIDA]])+IF(Rel_2026[[#This Row],[qtd_microsseguro]]>0,1*Rel_2026[[#This Row],[qtd_microsseguro]])+IF(Rel_2026[[#This Row],[QTD_SEG_RESIDENCIAL]]>0,1*Rel_2026[[#This Row],[QTD_SEG_RESIDENCIAL]])+IF(Rel_2026[[#This Row],[QTD_PLANO_ODONTO]]>0,1*Rel_2026[[#This Row],[QTD_PLANO_ODONTO]])+IF(Rel_2026[[#This Row],[vlr_lime]]>0,1*ROUND(Rel_2026[[#This Row],[vlr_lime]]/100,0))+ROUND(IF(Rel_2026[[#This Row],[VLR_CREDITO_PARCEL]]>500,1*Rel_2026[[#This Row],[VLR_CREDITO_PARCEL]]/500),0)+ROUND(Rel_2026[[#This Row],[vlr_consignado_total]]/1000,0)+ROUND(Rel_2026[[#This Row],[VLR_EXP_SORTE]]/50,0) -> 14 | AM5: =SUM(Rel_2026[[#This Row],[qtd_TrxContabil]:[VLR_EXP_SORTE]]) -> 561 | AN5: =IF(Rel_2026[[#This Row],[qtd_contas_com_deposito]]>0,7*Rel_2026[[#This Row],[qtd_contas_com_deposito]])+IF((Rel_2026[[#This Row],[qtd_contas]]-Rel_2026[[#This Row],[qtd_contas_com_deposito]])>0,(Rel_2026[[#This Row],[qtd_contas]]-Rel_2026[[#This Row],[qtd_contas_com_deposito]])*3)+IF(Rel_2026[[#This Row],[qtd_cesta_serv]]>0,3*Rel_2026[[#This Row],[qtd_cesta_serv]])+IF(Rel_2026[[#This Row],[QTD_CARTAO_EMITIDO]]>0,0*Rel_2026[[#This Row],[QTD_CARTAO_EMITIDO]])+IF(Rel_2026[[#This Row],[QTD_SUPER_PROTEGIDO]]>0,0*Rel_2026[[#This Row],[QTD_SUPER_PROTEGIDO]])+IF(Rel_2026[[#This Row],[QTD_CONTAS_PJ]]>0,0*Rel_2026[[#This Row],[QTD_CONTAS_PJ]])+IF(Rel_2026[[#This Row],[QTD_MICRO_VIVAVIDA]]>0,1*Rel_2026[[#This Row],[QTD_MICRO_VIVAVIDA]])+IF(Rel_2026[[#This Row],[qtd_microsseguro]]>0,1*Rel_2026[[#This Row],[qtd_microsseguro]])+IF(Rel_2026[[#This Row],[QTD_SEG_RESIDENCIAL]]>0,1*Rel_2026[[#This Row],[QTD_SEG_RESIDENCIAL]])+IF(Rel_2026[[#This Row],[QTD_PLANO_ODONTO]]>0,1*Rel_2026[[#This Row],[QTD_PLANO_ODONTO]])+IF(Rel_2026[[#This Row],[vlr_lime]]>0,1*ROUND(Rel_2026[[#This Row],[vlr_lime]]/100,0))+ROUND(IF(Rel_2026[[#This Row],[VLR_CREDITO_PARCEL]]>500,1*Rel_2026[[#This Row],[VLR_CREDITO_PARCEL]]/500),0)+ROUND(Rel_2026[[#This Row],[vlr_consignado_total]]/1000,0)+ROUND(Rel_2026[[#This Row],[VLR_EXP_SORTE]]/50,0) -> 17
A6: =IF(Rel_2026[[#This Row],[Zero]]=0,"Zero",IF(Rel_2026[[#This Row],[Pontuação]]>=10,"Sim",IF(Rel_2026[[#This Row],[Pontuação]]>=5,"Próximo","Não"))) -> Sim | B6: =IF(Rel_2026[[#This Row],[Zero]]=0,"Zero",IF(Rel_2026[[#This Row],[Pontuação2]]>=10,"Sim",IF(Rel_2026[[#This Row],[Pontuação2]]>=5,"Próximo","Não"))) -> Sim | C6: =IFERROR(VLOOKUP(Rel_2026[[#This Row],[chave_loja]],Responsavel!A:B,2,FALSE),"EUCLIDES") -> NYCOLLAS | D6: =LEFT(Rel_2026[[#This Row],[ag_pacb]],4) -> 5443 | E6: 248370 | F6: BELLOPE CALCADOS | G6: 5443/103 | H6: 45082 | I6: CE | J6: PARACURU | K6: 45306 | L6: 45131 | M6: FORTALEZA OESTE | N6: 46254 | O6: 99 | P6: 2 | Q6: 2 | R6: 2 | S6: 0 | T6: 0 | U6: 0 | V6: 0 | W6: 0 | X6: 0 | Y6: 0 | Z6: 0 | AA6: 0 | AB6: 0 | AC6: 0 | AD6: 0 | AE6: 0 | AF6: 0 | AG6: 0 | AH6: Nao | AI6: Desbloqueado | AK6: TREINADO | AL6: =IF(Rel_2026[[#This Row],[qtd_contas_com_deposito]]>0,7*Rel_2026[[#This Row],[qtd_contas_com_deposito]])+IF((Rel_2026[[#This Row],[qtd_contas]]-Rel_2026[[#This Row],[qtd_contas_com_deposito]])>0,(Rel_2026[[#This Row],[qtd_contas]]-Rel_2026[[#This Row],[qtd_contas_com_deposito]])*3)+IF(Rel_2026[[#This Row],[qtd_cesta_serv]]>0,0*Rel_2026[[#This Row],[qtd_cesta_serv]])+IF(Rel_2026[[#This Row],[QTD_CARTAO_EMITIDO]]>0,0*Rel_2026[[#This Row],[QTD_CARTAO_EMITIDO]])+IF(Rel_2026[[#This Row],[QTD_SUPER_PROTEGIDO]]>0,0*Rel_2026[[#This Row],[QTD_SUPER_PROTEGIDO]])+IF(Rel_2026[[#This Row],[QTD_CONTAS_PJ]]>0,0*Rel_2026[[#This Row],[QTD_CONTAS_PJ]])+IF(Rel_2026[[#This Row],[QTD_MICRO_VIVAVIDA]]>0,1*Rel_2026[[#This Row],[QTD_MICRO_VIVAVIDA]])+IF(Rel_2026[[#This Row],[qtd_microsseguro]]>0,1*Rel_2026[[#This Row],[qtd_microsseguro]])+IF(Rel_2026[[#This Row],[QTD_SEG_RESIDENCIAL]]>0,1*Rel_2026[[#This Row],[QTD_SEG_RESIDENCIAL]])+IF(Rel_2026[[#This Row],[QTD_PLANO_ODONTO]]>0,1*Rel_2026[[#This Row],[QTD_PLANO_ODONTO]])+IF(Rel_2026[[#This Row],[vlr_lime]]>0,1*ROUND(Rel_2026[[#This Row],[vlr_lime]]/100,0))+ROUND(IF(Rel_2026[[#This Row],[VLR_CREDITO_PARCEL]]>500,1*Rel_2026[[#This Row],[VLR_CREDITO_PARCEL]]/500),0)+ROUND(Rel_2026[[#This Row],[vlr_consignado_total]]/1000,0)+ROUND(Rel_2026[[#This Row],[VLR_EXP_SORTE]]/50,0) -> 14 | AM6: =SUM(Rel_2026[[#This Row],[qtd_TrxContabil]:[VLR_EXP_SORTE]]) -> 105 | AN6: =IF(Rel_2026[[#This Row],[qtd_contas_com_deposito]]>0,7*Rel_2026[[#This Row],[qtd_contas_com_deposito]])+IF((Rel_2026[[#This Row],[qtd_contas]]-Rel_2026[[#This Row],[qtd_contas_com_deposito]])>0,(Rel_2026[[#This Row],[qtd_contas]]-Rel_2026[[#This Row],[qtd_contas_com_deposito]])*3)+IF(Rel_2026[[#This Row],[qtd_cesta_serv]]>0,3*Rel_2026[[#This Row],[qtd_cesta_serv]])+IF(Rel_2026[[#This Row],[QTD_CARTAO_EMITIDO]]>0,0*Rel_2026[[#This Row],[QTD_CARTAO_EMITIDO]])+IF(Rel_2026[[#This Row],[QTD_SUPER_PROTEGIDO]]>0,0*Rel_2026[[#This Row],[QTD_SUPER_PROTEGIDO]])+IF(Rel_2026[[#This Row],[QTD_CONTAS_PJ]]>0,0*Rel_2026[[#This Row],[QTD_CONTAS_PJ]])+IF(Rel_2026[[#This Row],[QTD_MICRO_VIVAVIDA]]>0,1*Rel_2026[[#This Row],[QTD_MICRO_VIVAVIDA]])+IF(Rel_2026[[#This Row],[qtd_microsseguro]]>0,1*Rel_2026[[#This Row],[qtd_microsseguro]])+IF(Rel_2026[[#This Row],[QTD_SEG_RESIDENCIAL]]>0,1*Rel_2026[[#This Row],[QTD_SEG_RESIDENCIAL]])+IF(Rel_2026[[#This Row],[QTD_PLANO_ODONTO]]>0,1*Rel_2026[[#This Row],[QTD_PLANO_ODONTO]])+IF(Rel_2026[[#This Row],[vlr_lime]]>0,1*ROUND(Rel_2026[[#This Row],[vlr_lime]]/100,0))+ROUND(IF(Rel_2026[[#This Row],[VLR_CREDITO_PARCEL]]>500,1*Rel_2026[[#This Row],[VLR_CREDITO_PARCEL]]/500),0)+ROUND(Rel_2026[[#This Row],[vlr_consignado_total]]/1000,0)+ROUND(Rel_2026[[#This Row],[VLR_EXP_SORTE]]/50,0) -> 20
A7: =IF(Rel_2026[[#This Row],[Zero]]=0,"Zero",IF(Rel_2026[[#This Row],[Pontuação]]>=10,"Sim",IF(Rel_2026[[#This Row],[Pontuação]]>=5,"Próximo","Não"))) -> Sim | B7: =IF(Rel_2026[[#This Row],[Zero]]=0,"Zero",IF(Rel_2026[[#This Row],[Pontuação2]]>=10,"Sim",IF(Rel_2026[[#This Row],[Pontuação2]]>=5,"Próximo","Não"))) -> Sim | C7: =IFERROR(VLOOKUP(Rel_2026[[#This Row],[chave_loja]],Responsavel!A:B,2,FALSE),"EUCLIDES") -> GIL | D7: =LEFT(Rel_2026[[#This Row],[ag_pacb]],4) -> 5387 | E7: 44568 | F7: COMERCIAL FROTA | G7: 5387/076 | H7: 45138 | I7: CE | J7: MARTINOPOLE | K7: 42137 | L7: 45468 | M7: FORTALEZA OESTE | N7: 46254 | O7: 2172 | P7: 10 | Q7: 0 | R7: 9 | S7: 1 | T7: 1866 | U7: 0 | V7: 0 | W7: 0 | X7: 0 | Y7: 0 | Z7: 0 | AA7: 0 | AB7: 0 | AC7: 0 | AD7: 0 | AE7: 0 | AF7: 1 | AG7: 0 | AH7: Sim | AI7: Desbloqueado | AK7: TREINADO | AL7: =IF(Rel_2026[[#This Row],[qtd_contas_com_deposito]]>0,7*Rel_2026[[#This Row],[qtd_contas_com_deposito]])+IF((Rel_2026[[#This Row],[qtd_contas]]-Rel_2026[[#This Row],[qtd_contas_com_deposito]])>0,(Rel_2026[[#This Row],[qtd_contas]]-Rel_2026[[#This Row],[qtd_contas_com_deposito]])*3)+IF(Rel_2026[[#This Row],[qtd_cesta_serv]]>0,0*Rel_2026[[#This Row],[qtd_cesta_serv]])+IF(Rel_2026[[#This Row],[QTD_CARTAO_EMITIDO]]>0,0*Rel_2026[[#This Row],[QTD_CARTAO_EMITIDO]])+IF(Rel_2026[[#This Row],[QTD_SUPER_PROTEGIDO]]>0,0*Rel_2026[[#This Row],[QTD_SUPER_PROTEGIDO]])+IF(Rel_2026[[#This Row],[QTD_CONTAS_PJ]]>0,0*Rel_2026[[#This Row],[QTD_CONTAS_PJ]])+IF(Rel_2026[[#This Row],[QTD_MICRO_VIVAVIDA]]>0,1*Rel_2026[[#This Row],[QTD_MICRO_VIVAVIDA]])+IF(Rel_2026[[#This Row],[qtd_microsseguro]]>0,1*Rel_2026[[#This Row],[qtd_microsseguro]])+IF(Rel_2026[[#This Row],[QTD_SEG_RESIDENCIAL]]>0,1*Rel_2026[[#This Row],[QTD_SEG_RESIDENCIAL]])+IF(Rel_2026[[#This Row],[QTD_PLANO_ODONTO]]>0,1*Rel_2026[[#This Row],[QTD_PLANO_ODONTO]])+IF(Rel_2026[[#This Row],[vlr_lime]]>0,1*ROUND(Rel_2026[[#This Row],[vlr_lime]]/100,0))+ROUND(IF(Rel_2026[[#This Row],[VLR_CREDITO_PARCEL]]>500,1*Rel_2026[[#This Row],[VLR_CREDITO_PARCEL]]/500),0)+ROUND(Rel_2026[[#This Row],[vlr_consignado_total]]/1000,0)+ROUND(Rel_2026[[#This Row],[VLR_EXP_SORTE]]/50,0) -> 49 | AM7: =SUM(Rel_2026[[#This Row],[qtd_TrxContabil]:[VLR_EXP_SORTE]]) -> 4059 | AN7: =IF(Rel_2026[[#This Row],[qtd_contas_com_deposito]]>0,7*Rel_2026[[#This Row],[qtd_contas_com_deposito]])+IF((Rel_2026[[#This Row],[qtd_contas]]-Rel_2026[[#This Row],[qtd_contas_com_deposito]])>0,(Rel_2026[[#This Row],[qtd_contas]]-Rel_2026[[#This Row],[qtd_contas_com_deposito]])*3)+IF(Rel_2026[[#This Row],[qtd_cesta_serv]]>0,3*Rel_2026[[#This Row],[qtd_cesta_serv]])+IF(Rel_2026[[#This Row],[QTD_CARTAO_EMITIDO]]>0,0*Rel_2026[[#This Row],[QTD_CARTAO_EMITIDO]])+IF(Rel_2026[[#This Row],[QTD_SUPER_PROTEGIDO]]>0,0*Rel_2026[[#This Row],[QTD_SUPER_PROTEGIDO]])+IF(Rel_2026[[#This Row],[QTD_CONTAS_PJ]]>0,0*Rel_2026[[#This Row],[QTD_CONTAS_PJ]])+IF(Rel_2026[[#This Row],[QTD_MICRO_VIVAVIDA]]>0,1*Rel_2026[[#This Row],[QTD_MICRO_VIVAVIDA]])+IF(Rel_2026[[#This Row],[qtd_microsseguro]]>0,1*Rel_2026[[#This Row],[qtd_microsseguro]])+IF(Rel_2026[[#This Row],[QTD_SEG_RESIDENCIAL]]>0,1*Rel_2026[[#This Row],[QTD_SEG_RESIDENCIAL]])+IF(Rel_2026[[#This Row],[QTD_PLANO_ODONTO]]>0,1*Rel_2026[[#This Row],[QTD_PLANO_ODONTO]])+IF(Rel_2026[[#This Row],[vlr_lime]]>0,1*ROUND(Rel_2026[[#This Row],[vlr_lime]]/100,0))+ROUND(IF(Rel_2026[[#This Row],[VLR_CREDITO_PARCEL]]>500,1*Rel_2026[[#This Row],[VLR_CREDITO_PARCEL]]/500),0)+ROUND(Rel_2026[[#This Row],[vlr_consignado_total]]/1000,0)+ROUND(Rel_2026[[#This Row],[VLR_EXP_SORTE]]/50,0) -> 76
A8: =IF(Rel_2026[[#This Row],[Zero]]=0,"Zero",IF(Rel_2026[[#This Row],[Pontuação]]>=10,"Sim",IF(Rel_2026[[#This Row],[Pontuação]]>=5,"Próximo","Não"))) -> Não | B8: =IF(Rel_2026[[#This Row],[Zero]]=0,"Zero",IF(Rel_2026[[#This Row],[Pontuação2]]>=10,"Sim",IF(Rel_2026[[#This Row],[Pontuação2]]>=5,"Próximo","Não"))) -> Não | C8: =IFERROR(VLOOKUP(Rel_2026[[#This Row],[chave_loja]],Responsavel!A:B,2,FALSE),"EUCLIDES") -> JACK | D8: =LEFT(Rel_2026[[#This Row],[ag_pacb]],4) -> 5808 | E8: 147670 | F8: FARMACIA N S DO CARMO | G8: 5808/089 | H8: 45204 | I8: PI | J8: PIRIPIRI | K8: 42636 | L8: 44572 | M8: TERESINA | N8: 46254 | O8: 318 | P8: 0 | Q8: 0 | R8: 0 | S8: 0 | T8: 0 | U8: 0 | V8: 0 | W8: 0 | X8: 0 | Y8: 0 | Z8: 0 | AA8: 0 | AB8: 0 | AC8: 0 | AD8: 0 | AE8: 0 | AF8: 0 | AG8: 0 | AH8: Nao | AI8: Desbloqueado | AK8: TREINADO | AL8: =IF(Rel_2026[[#This Row],[qtd_contas_com_deposito]]>0,7*Rel_2026[[#This Row],[qtd_contas_com_deposito]])+IF((Rel_2026[[#This Row],[qtd_contas]]-Rel_2026[[#This Row],[qtd_contas_com_deposito]])>0,(Rel_2026[[#This Row],[qtd_contas]]-Rel_2026[[#This Row],[qtd_contas_com_deposito]])*3)+IF(Rel_2026[[#This Row],[qtd_cesta_serv]]>0,0*Rel_2026[[#This Row],[qtd_cesta_serv]])+IF(Rel_2026[[#This Row],[QTD_CARTAO_EMITIDO]]>0,0*Rel_2026[[#This Row],[QTD_CARTAO_EMITIDO]])+IF(Rel_2026[[#This Row],[QTD_SUPER_PROTEGIDO]]>0,0*Rel_2026[[#This Row],[QTD_SUPER_PROTEGIDO]])+IF(Rel_2026[[#This Row],[QTD_CONTAS_PJ]]>0,0*Rel_2026[[#This Row],[QTD_CONTAS_PJ]])+IF(Rel_2026[[#This Row],[QTD_MICRO_VIVAVIDA]]>0,1*Rel_2026[[#This Row],[QTD_MICRO_VIVAVIDA]])+IF(Rel_2026[[#This Row],[qtd_microsseguro]]>0,1*Rel_2026[[#This Row],[qtd_microsseguro]])+IF(Rel_2026[[#This Row],[QTD_SEG_RESIDENCIAL]]>0,1*Rel_2026[[#This Row],[QTD_SEG_RESIDENCIAL]])+IF(Rel_2026[[#This Row],[QTD_PLANO_ODONTO]]>0,1*Rel_2026[[#This Row],[QTD_PLANO_ODONTO]])+IF(Rel_2026[[#This Row],[vlr_lime]]>0,1*ROUND(Rel_2026[[#This Row],[vlr_lime]]/100,0))+ROUND(IF(Rel_2026[[#This Row],[VLR_CREDITO_PARCEL]]>500,1*Rel_2026[[#This Row],[VLR_CREDITO_PARCEL]]/500),0)+ROUND(Rel_2026[[#This Row],[vlr_consignado_total]]/1000,0)+ROUND(Rel_2026[[#This Row],[VLR_EXP_SORTE]]/50,0) -> 0 | AM8: =SUM(Rel_2026[[#This Row],[qtd_TrxContabil]:[VLR_EXP_SORTE]]) -> 318 | AN8: =IF(Rel_2026[[#This Row],[qtd_contas_com_deposito]]>0,7*Rel_2026[[#This Row],[qtd_contas_com_deposito]])+IF((Rel_2026[[#This Row],[qtd_contas]]-Rel_2026[[#This Row],[qtd_contas_com_deposito]])>0,(Rel_2026[[#This Row],[qtd_contas]]-Rel_2026[[#This Row],[qtd_contas_com_deposito]])*3)+IF(Rel_2026[[#This Row],[qtd_cesta_serv]]>0,3*Rel_2026[[#This Row],[qtd_cesta_serv]])+IF(Rel_2026[[#This Row],[QTD_CARTAO_EMITIDO]]>0,0*Rel_2026[[#This Row],[QTD_CARTAO_EMITIDO]])+IF(Rel_2026[[#This Row],[QTD_SUPER_PROTEGIDO]]>0,0*Rel_2026[[#This Row],[QTD_SUPER_PROTEGIDO]])+IF(Rel_2026[[#This Row],[QTD_CONTAS_PJ]]>0,0*Rel_2026[[#This Row],[QTD_CONTAS_PJ]])+IF(Rel_2026[[#This Row],[QTD_MICRO_VIVAVIDA]]>0,1*Rel_2026[[#This Row],[QTD_MICRO_VIVAVIDA]])+IF(Rel_2026[[#This Row],[qtd_microsseguro]]>0,1*Rel_2026[[#This Row],[qtd_microsseguro]])+IF(Rel_2026[[#This Row],[QTD_SEG_RESIDENCIAL]]>0,1*Rel_2026[[#This Row],[QTD_SEG_RESIDENCIAL]])+IF(Rel_2026[[#This Row],[QTD_PLANO_ODONTO]]>0,1*Rel_2026[[#This Row],[QTD_PLANO_ODONTO]])+IF(Rel_2026[[#This Row],[vlr_lime]]>0,1*ROUND(Rel_2026[[#This Row],[vlr_lime]]/100,0))+ROUND(IF(Rel_2026[[#This Row],[VLR_CREDITO_PARCEL]]>500,1*Rel_2026[[#This Row],[VLR_CREDITO_PARCEL]]/500),0)+ROUND(Rel_2026[[#This Row],[vlr_consignado_total]]/1000,0)+ROUND(Rel_2026[[#This Row],[VLR_EXP_SORTE]]/50,0) -> 0
A9: =IF(Rel_2026[[#This Row],[Zero]]=0,"Zero",IF(Rel_2026[[#This Row],[Pontuação]]>=10,"Sim",IF(Rel_2026[[#This Row],[Pontuação]]>=5,"Próximo","Não"))) -> Zero | B9: =IF(Rel_2026[[#This Row],[Zero]]=0,"Zero",IF(Rel_2026[[#This Row],[Pontuação2]]>=10,"Sim",IF(Rel_2026[[#This Row],[Pontuação2]]>=5,"Próximo","Não"))) -> Zero | C9: =IFERROR(VLOOKUP(Rel_2026[[#This Row],[chave_loja]],Responsavel!A:B,2,FALSE),"EUCLIDES") -> ALEX SIQUEIRA | D9: =LEFT(Rel_2026[[#This Row],[ag_pacb]],4) -> 0752 | E9: 415561 | F9: Posto De Medicamentos Sao Lucas | G9: 0752/139 | H9: 45880 | I9: CE | J9: UBAJARA | K9: 45875 | L9: 45890 | M9: TERESINA | N9: 46104 | O9: 0 | P9: 0 | Q9: 0 | R9: 0 | S9: 0 | T9: 0 | U9: 0 | V9: 0 | W9: 0 | X9: 0 | Y9: 0 | Z9: 0 | AA9: 0 | AB9: 0 | AC9: 0 | AD9: 0 | AE9: 0 | AF9: 0 | AG9: 0 | AH9: Nao | AI9: Bloqueado | AJ9: 46199 | AK9: TREINADO | AL9: =IF(Rel_2026[[#This Row],[qtd_contas_com_deposito]]>0,7*Rel_2026[[#This Row],[qtd_contas_com_deposito]])+IF((Rel_2026[[#This Row],[qtd_contas]]-Rel_2026[[#This Row],[qtd_contas_com_deposito]])>0,(Rel_2026[[#This Row],[qtd_contas]]-Rel_2026[[#This Row],[qtd_contas_com_deposito]])*3)+IF(Rel_2026[[#This Row],[qtd_cesta_serv]]>0,0*Rel_2026[[#This Row],[qtd_cesta_serv]])+IF(Rel_2026[[#This Row],[QTD_CARTAO_EMITIDO]]>0,0*Rel_2026[[#This Row],[QTD_CARTAO_EMITIDO]])+IF(Rel_2026[[#This Row],[QTD_SUPER_PROTEGIDO]]>0,0*Rel_2026[[#This Row],[QTD_SUPER_PROTEGIDO]])+IF(Rel_2026[[#This Row],[QTD_CONTAS_PJ]]>0,0*Rel_2026[[#This Row],[QTD_CONTAS_PJ]])+IF(Rel_2026[[#This Row],[QTD_MICRO_VIVAVIDA]]>0,1*Rel_2026[[#This Row],[QTD_MICRO_VIVAVIDA]])+IF(Rel_2026[[#This Row],[qtd_microsseguro]]>0,1*Rel_2026[[#This Row],[qtd_microsseguro]])+IF(Rel_2026[[#This Row],[QTD_SEG_RESIDENCIAL]]>0,1*Rel_2026[[#This Row],[QTD_SEG_RESIDENCIAL]])+IF(Rel_2026[[#This Row],[QTD_PLANO_ODONTO]]>0,1*Rel_2026[[#This Row],[QTD_PLANO_ODONTO]])+IF(Rel_2026[[#This Row],[vlr_lime]]>0,1*ROUND(Rel_2026[[#This Row],[vlr_lime]]/100,0))+ROUND(IF(Rel_2026[[#This Row],[VLR_CREDITO_PARCEL]]>500,1*Rel_2026[[#This Row],[VLR_CREDITO_PARCEL]]/500),0)+ROUND(Rel_2026[[#This Row],[vlr_consignado_total]]/1000,0)+ROUND(Rel_2026[[#This Row],[VLR_EXP_SORTE]]/50,0) -> 0 | AM9: =SUM(Rel_2026[[#This Row],[qtd_TrxContabil]:[VLR_EXP_SORTE]]) -> 0 | AN9: =IF(Rel_2026[[#This Row],[qtd_contas_com_deposito]]>0,7*Rel_2026[[#This Row],[qtd_contas_com_deposito]])+IF((Rel_2026[[#This Row],[qtd_contas]]-Rel_2026[[#This Row],[qtd_contas_com_deposito]])>0,(Rel_2026[[#This Row],[qtd_contas]]-Rel_2026[[#This Row],[qtd_contas_com_deposito]])*3)+IF(Rel_2026[[#This Row],[qtd_cesta_serv]]>0,3*Rel_2026[[#This Row],[qtd_cesta_serv]])+IF(Rel_2026[[#This Row],[QTD_CARTAO_EMITIDO]]>0,0*Rel_2026[[#This Row],[QTD_CARTAO_EMITIDO]])+IF(Rel_2026[[#This Row],[QTD_SUPER_PROTEGIDO]]>0,0*Rel_2026[[#This Row],[QTD_SUPER_PROTEGIDO]])+IF(Rel_2026[[#This Row],[QTD_CONTAS_PJ]]>0,0*Rel_2026[[#This Row],[QTD_CONTAS_PJ]])+IF(Rel_2026[[#This Row],[QTD_MICRO_VIVAVIDA]]>0,1*Rel_2026[[#This Row],[QTD_MICRO_VIVAVIDA]])+IF(Rel_2026[[#This Row],[qtd_microsseguro]]>0,1*Rel_2026[[#This Row],[qtd_microsseguro]])+IF(Rel_2026[[#This Row],[QTD_SEG_RESIDENCIAL]]>0,1*Rel_2026[[#This Row],[QTD_SEG_RESIDENCIAL]])+IF(Rel_2026[[#This Row],[QTD_PLANO_ODONTO]]>0,1*Rel_2026[[#This Row],[QTD_PLANO_ODONTO]])+IF(Rel_2026[[#This Row],[vlr_lime]]>0,1*ROUND(Rel_2026[[#This Row],[vlr_lime]]/100,0))+ROUND(IF(Rel_2026[[#This Row],[VLR_CREDITO_PARCEL]]>500,1*Rel_2026[[#This Row],[VLR_CREDITO_PARCEL]]/500),0)+ROUND(Rel_2026[[#This Row],[vlr_consignado_total]]/1000,0)+ROUND(Rel_2026[[#This Row],[VLR_EXP_SORTE]]/50,0) -> 0
A10: =IF(Rel_2026[[#This Row],[Zero]]=0,"Zero",IF(Rel_2026[[#This Row],[Pontuação]]>=10,"Sim",IF(Rel_2026[[#This Row],[Pontuação]]>=5,"Próximo","Não"))) -> Sim | B10: =IF(Rel_2026[[#This Row],[Zero]]=0,"Zero",IF(Rel_2026[[#This Row],[Pontuação2]]>=10,"Sim",IF(Rel_2026[[#This Row],[Pontuação2]]>=5,"Próximo","Não"))) -> Sim | C10: =IFERROR(VLOOKUP(Rel_2026[[#This Row],[chave_loja]],Responsavel!A:B,2,FALSE),"EUCLIDES") -> ROSSY | D10: =LEFT(Rel_2026[[#This Row],[ag_pacb]],4) -> 5792 | E10: 153607 | F10: DROGARIA PAGUE BEM | G10: 5792/120 | H10: 45127 | I10: PI | J10: CABECEIRAS DO PIAUI | K10: 42636 | L10: 46156 | M10: TERESINA | N10: 46254 | O10: 795 | P10: 3 | Q10: 0 | R10: 3 | S10: 0 | T10: 0 | U10: 0 | V10: 0 | W10: 0 | X10: 0 | Y10: 0 | Z10: 0 | AA10: 1 | AB10: 0 | AC10: 0 | AD10: 0 | AE10: 0 | AF10: 2 | AG10: 0 | AH10: Sim | AI10: Desbloqueado | AK10: TREINADO | AL10: =IF(Rel_2026[[#This Row],[qtd_contas_com_deposito]]>0,7*Rel_2026[[#This Row],[qtd_contas_com_deposito]])+IF((Rel_2026[[#This Row],[qtd_contas]]-Rel_2026[[#This Row],[qtd_contas_com_deposito]])>0,(Rel_2026[[#This Row],[qtd_contas]]-Rel_2026[[#This Row],[qtd_contas_com_deposito]])*3)+IF(Rel_2026[[#This Row],[qtd_cesta_serv]]>0,0*Rel_2026[[#This Row],[qtd_cesta_serv]])+IF(Rel_2026[[#This Row],[QTD_CARTAO_EMITIDO]]>0,0*Rel_2026[[#This Row],[QTD_CARTAO_EMITIDO]])+IF(Rel_2026[[#This Row],[QTD_SUPER_PROTEGIDO]]>0,0*Rel_2026[[#This Row],[QTD_SUPER_PROTEGIDO]])+IF(Rel_2026[[#This Row],[QTD_CONTAS_PJ]]>0,0*Rel_2026[[#This Row],[QTD_CONTAS_PJ]])+IF(Rel_2026[[#This Row],[QTD_MICRO_VIVAVIDA]]>0,1*Rel_2026[[#This Row],[QTD_MICRO_VIVAVIDA]])+IF(Rel_2026[[#This Row],[qtd_microsseguro]]>0,1*Rel_2026[[#This Row],[qtd_microsseguro]])+IF(Rel_2026[[#This Row],[QTD_SEG_RESIDENCIAL]]>0,1*Rel_2026[[#This Row],[QTD_SEG_RESIDENCIAL]])+IF(Rel_2026[[#This Row],[QTD_PLANO_ODONTO]]>0,1*Rel_2026[[#This Row],[QTD_PLANO_ODONTO]])+IF(Rel_2026[[#This Row],[vlr_lime]]>0,1*ROUND(Rel_2026[[#This Row],[vlr_lime]]/100,0))+ROUND(IF(Rel_2026[[#This Row],[VLR_CREDITO_PARCEL]]>500,1*Rel_2026[[#This Row],[VLR_CREDITO_PARCEL]]/500),0)+ROUND(Rel_2026[[#This Row],[vlr_consignado_total]]/1000,0)+ROUND(Rel_2026[[#This Row],[VLR_EXP_SORTE]]/50,0) -> 10 | AM10: =SUM(Rel_2026[[#This Row],[qtd_TrxContabil]:[VLR_EXP_SORTE]]) -> 804 | AN10: =IF(Rel_2026[[#This Row],[qtd_contas_com_deposito]]>0,7*Rel_2026[[#This Row],[qtd_contas_com_deposito]])+IF((Rel_2026[[#This Row],[qtd_contas]]-Rel_2026[[#This Row],[qtd_contas_com_deposito]])>0,(Rel_2026[[#This Row],[qtd_contas]]-Rel_2026[[#This Row],[qtd_contas_com_deposito]])*3)+IF(Rel_2026[[#This Row],[qtd_cesta_serv]]>0,3*Rel_2026[[#This Row],[qtd_cesta_serv]])+IF(Rel_2026[[#This Row],[QTD_CARTAO_EMITIDO]]>0,0*Rel_2026[[#This Row],[QTD_CARTAO_EMITIDO]])+IF(Rel_2026[[#This Row],[QTD_SUPER_PROTEGIDO]]>0,0*Rel_2026[[#This Row],[QTD_SUPER_PROTEGIDO]])+IF(Rel_2026[[#This Row],[QTD_CONTAS_PJ]]>0,0*Rel_2026[[#This Row],[QTD_CONTAS_PJ]])+IF(Rel_2026[[#This Row],[QTD_MICRO_VIVAVIDA]]>0,1*Rel_2026[[#This Row],[QTD_MICRO_VIVAVIDA]])+IF(Rel_2026[[#This Row],[qtd_microsseguro]]>0,1*Rel_2026[[#This Row],[qtd_microsseguro]])+IF(Rel_2026[[#This Row],[QTD_SEG_RESIDENCIAL]]>0,1*Rel_2026[[#This Row],[QTD_SEG_RESIDENCIAL]])+IF(Rel_2026[[#This Row],[QTD_PLANO_ODONTO]]>0,1*Rel_2026[[#This Row],[QTD_PLANO_ODONTO]])+IF(Rel_2026[[#This Row],[vlr_lime]]>0,1*ROUND(Rel_2026[[#This Row],[vlr_lime]]/100,0))+ROUND(IF(Rel_2026[[#This Row],[VLR_CREDITO_PARCEL]]>500,1*Rel_2026[[#This Row],[VLR_CREDITO_PARCEL]]/500),0)+ROUND(Rel_2026[[#This Row],[vlr_consignado_total]]/1000,0)+ROUND(Rel_2026[[#This Row],[VLR_EXP_SORTE]]/50,0) -> 19
A11: =IF(Rel_2026[[#This Row],[Zero]]=0,"Zero",IF(Rel_2026[[#This Row],[Pontuação]]>=10,"Sim",IF(Rel_2026[[#This Row],[Pontuação]]>=5,"Próximo","Não"))) -> Não | B11: =IF(Rel_2026[[#This Row],[Zero]]=0,"Zero",IF(Rel_2026[[#This Row],[Pontuação2]]>=10,"Sim",IF(Rel_2026[[#This Row],[Pontuação2]]>=5,"Próximo","Não"))) -> Não | C11: =IFERROR(VLOOKUP(Rel_2026[[#This Row],[chave_loja]],Responsavel!A:B,2,FALSE),"EUCLIDES") -> DARIO | D11: =LEFT(Rel_2026[[#This Row],[ag_pacb]],4) -> 1781 | E11: 221909 | F11: NOSSO ATACAREJO LIMOEIRO | G11: 1781/132 | H11: 45107 | I11: CE | J11: LIMOEIRO DO NORTE | K11: 45306 | L11: 45175 | M11: FORTALEZA LESTE | N11: 46254 | O11: 1709 | P11: 0 | Q11: 0 | R11: 0 | S11: 0 | T11: 0 | U11: 0 | V11: 0 | W11: 0 | X11: 0 | Y11: 0 | Z11: 0 | AA11: 0 | AB11: 0 | AC11: 0 | AD11: 0 | AE11: 0 | AF11: 0 | AG11: 0 | AH11: Sim | AI11: Desbloqueado | AK11: TREINADO | AL11: =IF(Rel_2026[[#This Row],[qtd_contas_com_deposito]]>0,7*Rel_2026[[#This Row],[qtd_contas_com_deposito]])+IF((Rel_2026[[#This Row],[qtd_contas]]-Rel_2026[[#This Row],[qtd_contas_com_deposito]])>0,(Rel_2026[[#This Row],[qtd_contas]]-Rel_2026[[#This Row],[qtd_contas_com_deposito]])*3)+IF(Rel_2026[[#This Row],[qtd_cesta_serv]]>0,0*Rel_2026[[#This Row],[qtd_cesta_serv]])+IF(Rel_2026[[#This Row],[QTD_CARTAO_EMITIDO]]>0,0*Rel_2026[[#This Row],[QTD_CARTAO_EMITIDO]])+IF(Rel_2026[[#This Row],[QTD_SUPER_PROTEGIDO]]>0,0*Rel_2026[[#This Row],[QTD_SUPER_PROTEGIDO]])+IF(Rel_2026[[#This Row],[QTD_CONTAS_PJ]]>0,0*Rel_2026[[#This Row],[QTD_CONTAS_PJ]])+IF(Rel_2026[[#This Row],[QTD_MICRO_VIVAVIDA]]>0,1*Rel_2026[[#This Row],[QTD_MICRO_VIVAVIDA]])+IF(Rel_2026[[#This Row],[qtd_microsseguro]]>0,1*Rel_2026[[#This Row],[qtd_microsseguro]])+IF(Rel_2026[[#This Row],[QTD_SEG_RESIDENCIAL]]>0,1*Rel_2026[[#This Row],[QTD_SEG_RESIDENCIAL]])+IF(Rel_2026[[#This Row],[QTD_PLANO_ODONTO]]>0,1*Rel_2026[[#This Row],[QTD_PLANO_ODONTO]])+IF(Rel_2026[[#This Row],[vlr_lime]]>0,1*ROUND(Rel_2026[[#This Row],[vlr_lime]]/100,0))+ROUND(IF(Rel_2026[[#This Row],[VLR_CREDITO_PARCEL]]>500,1*Rel_2026[[#This Row],[VLR_CREDITO_PARCEL]]/500),0)+ROUND(Rel_2026[[#This Row],[vlr_consignado_total]]/1000,0)+ROUND(Rel_2026[[#This Row],[VLR_EXP_SORTE]]/50,0) -> 0 | AM11: =SUM(Rel_2026[[#This Row],[qtd_TrxContabil]:[VLR_EXP_SORTE]]) -> 1709 | AN11: =IF(Rel_2026[[#This Row],[qtd_contas_com_deposito]]>0,7*Rel_2026[[#This Row],[qtd_contas_com_deposito]])+IF((Rel_2026[[#This Row],[qtd_contas]]-Rel_2026[[#This Row],[qtd_contas_com_deposito]])>0,(Rel_2026[[#This Row],[qtd_contas]]-Rel_2026[[#This Row],[qtd_contas_com_deposito]])*3)+IF(Rel_2026[[#This Row],[qtd_cesta_serv]]>0,3*Rel_2026[[#This Row],[qtd_cesta_serv]])+IF(Rel_2026[[#This Row],[QTD_CARTAO_EMITIDO]]>0,0*Rel_2026[[#This Row],[QTD_CARTAO_EMITIDO]])+IF(Rel_2026[[#This Row],[QTD_SUPER_PROTEGIDO]]>0,0*Rel_2026[[#This Row],[QTD_SUPER_PROTEGIDO]])+IF(Rel_2026[[#This Row],[QTD_CONTAS_PJ]]>0,0*Rel_2026[[#This Row],[QTD_CONTAS_PJ]])+IF(Rel_2026[[#This Row],[QTD_MICRO_VIVAVIDA]]>0,1*Rel_2026[[#This Row],[QTD_MICRO_VIVAVIDA]])+IF(Rel_2026[[#This Row],[qtd_microsseguro]]>0,1*Rel_2026[[#This Row],[qtd_microsseguro]])+IF(Rel_2026[[#This Row],[QTD_SEG_RESIDENCIAL]]>0,1*Rel_2026[[#This Row],[QTD_SEG_RESIDENCIAL]])+IF(Rel_2026[[#This Row],[QTD_PLANO_ODONTO]]>0,1*Rel_2026[[#This Row],[QTD_PLANO_ODONTO]])+IF(Rel_2026[[#This Row],[vlr_lime]]>0,1*ROUND(Rel_2026[[#This Row],[vlr_lime]]/100,0))+ROUND(IF(Rel_2026[[#This Row],[VLR_CREDITO_PARCEL]]>500,1*Rel_2026[[#This Row],[VLR_CREDITO_PARCEL]]/500),0)+ROUND(Rel_2026[[#This Row],[vlr_consignado_total]]/1000,0)+ROUND(Rel_2026[[#This Row],[VLR_EXP_SORTE]]/50,0) -> 0
A12: =IF(Rel_2026[[#This Row],[Zero]]=0,"Zero",IF(Rel_2026[[#This Row],[Pontuação]]>=10,"Sim",IF(Rel_2026[[#This Row],[Pontuação]]>=5,"Próximo","Não"))) -> Não | B12: =IF(Rel_2026[[#This Row],[Zero]]=0,"Zero",IF(Rel_2026[[#This Row],[Pontuação2]]>=10,"Sim",IF(Rel_2026[[#This Row],[Pontuação2]]>=5,"Próximo","Não"))) -> Não | C12: =IFERROR(VLOOKUP(Rel_2026[[#This Row],[chave_loja]],Responsavel!A:B,2,FALSE),"EUCLIDES") -> JUNIOR | D12: =LEFT(Rel_2026[[#This Row],[ag_pacb]],4) -> 0684 | E12: 242211 | F12: MERCADINHO POMPEU | G12: 0684/192 | H12: 45161 | I12: CE | J12: ACARAU | K12: 44951 | L12: 46065 | M12: FORTALEZA OESTE | N12: 46252 | O12: 78 | P12: 0 | Q12: 0 | R12: 0 | S12: 0 | T12: 0 | U12: 0 | V12: 0 | W12: 0 | X12: 0 | Y12: 0 | Z12: 0 | AA12: 0 | AB12: 0 | AC12: 0 | AD12: 0 | AE12: 0 | AF12: 0 | AG12: 0 | AH12: Nao | AI12: Desbloqueado | AK12: TREINADO | AL12: =IF(Rel_2026[[#This Row],[qtd_contas_com_deposito]]>0,7*Rel_2026[[#This Row],[qtd_contas_com_deposito]])+IF((Rel_2026[[#This Row],[qtd_contas]]-Rel_2026[[#This Row],[qtd_contas_com_deposito]])>0,(Rel_2026[[#This Row],[qtd_contas]]-Rel_2026[[#This Row],[qtd_contas_com_deposito]])*3)+IF(Rel_2026[[#This Row],[qtd_cesta_serv]]>0,0*Rel_2026[[#This Row],[qtd_cesta_serv]])+IF(Rel_2026[[#This Row],[QTD_CARTAO_EMITIDO]]>0,0*Rel_2026[[#This Row],[QTD_CARTAO_EMITIDO]])+IF(Rel_2026[[#This Row],[QTD_SUPER_PROTEGIDO]]>0,0*Rel_2026[[#This Row],[QTD_SUPER_PROTEGIDO]])+IF(Rel_2026[[#This Row],[QTD_CONTAS_PJ]]>0,0*Rel_2026[[#This Row],[QTD_CONTAS_PJ]])+IF(Rel_2026[[#This Row],[QTD_MICRO_VIVAVIDA]]>0,1*Rel_2026[[#This Row],[QTD_MICRO_VIVAVIDA]])+IF(Rel_2026[[#This Row],[qtd_microsseguro]]>0,1*Rel_2026[[#This Row],[qtd_microsseguro]])+IF(Rel_2026[[#This Row],[QTD_SEG_RESIDENCIAL]]>0,1*Rel_2026[[#This Row],[QTD_SEG_RESIDENCIAL]])+IF(Rel_2026[[#This Row],[QTD_PLANO_ODONTO]]>0,1*Rel_2026[[#This Row],[QTD_PLANO_ODONTO]])+IF(Rel_2026[[#This Row],[vlr_lime]]>0,1*ROUND(Rel_2026[[#This Row],[vlr_lime]]/100,0))+ROUND(IF(Rel_2026[[#This Row],[VLR_CREDITO_PARCEL]]>500,1*Rel_2026[[#This Row],[VLR_CREDITO_PARCEL]]/500),0)+ROUND(Rel_2026[[#This Row],[vlr_consignado_total]]/1000,0)+ROUND(Rel_2026[[#This Row],[VLR_EXP_SORTE]]/50,0) -> 0 | AM12: =SUM(Rel_2026[[#This Row],[qtd_TrxContabil]:[VLR_EXP_SORTE]]) -> 78 | AN12: =IF(Rel_2026[[#This Row],[qtd_contas_com_deposito]]>0,7*Rel_2026[[#This Row],[qtd_contas_com_deposito]])+IF((Rel_2026[[#This Row],[qtd_contas]]-Rel_2026[[#This Row],[qtd_contas_com_deposito]])>0,(Rel_2026[[#This Row],[qtd_contas]]-Rel_2026[[#This Row],[qtd_contas_com_deposito]])*3)+IF(Rel_2026[[#This Row],[qtd_cesta_serv]]>0,3*Rel_2026[[#This Row],[qtd_cesta_serv]])+IF(Rel_2026[[#This Row],[QTD_CARTAO_EMITIDO]]>0,0*Rel_2026[[#This Row],[QTD_CARTAO_EMITIDO]])+IF(Rel_2026[[#This Row],[QTD_SUPER_PROTEGIDO]]>0,0*Rel_2026[[#This Row],[QTD_SUPER_PROTEGIDO]])+IF(Rel_2026[[#This Row],[QTD_CONTAS_PJ]]>0,0*Rel_2026[[#This Row],[QTD_CONTAS_PJ]])+IF(Rel_2026[[#This Row],[QTD_MICRO_VIVAVIDA]]>0,1*Rel_2026[[#This Row],[QTD_MICRO_VIVAVIDA]])+IF(Rel_2026[[#This Row],[qtd_microsseguro]]>0,1*Rel_2026[[#This Row],[qtd_microsseguro]])+IF(Rel_2026[[#This Row],[QTD_SEG_RESIDENCIAL]]>0,1*Rel_2026[[#This Row],[QTD_SEG_RESIDENCIAL]])+IF(Rel_2026[[#This Row],[QTD_PLANO_ODONTO]]>0,1*Rel_2026[[#This Row],[QTD_PLANO_ODONTO]])+IF(Rel_2026[[#This Row],[vlr_lime]]>0,1*ROUND(Rel_2026[[#This Row],[vlr_lime]]/100,0))+ROUND(IF(Rel_2026[[#This Row],[VLR_CREDITO_PARCEL]]>500,1*Rel_2026[[#This Row],[VLR_CREDITO_PARCEL]]/500),0)+ROUND(Rel_2026[[#This Row],[vlr_consignado_total]]/1000,0)+ROUND(Rel_2026[[#This Row],[VLR_EXP_SORTE]]/50,0) -> 0
A13: =IF(Rel_2026[[#This Row],[Zero]]=0,"Zero",IF(Rel_2026[[#This Row],[Pontuação]]>=10,"Sim",IF(Rel_2026[[#This Row],[Pontuação]]>=5,"Próximo","Não"))) -> Sim | B13: =IF(Rel_2026[[#This Row],[Zero]]=0,"Zero",IF(Rel_2026[[#This Row],[Pontuação2]]>=10,"Sim",IF(Rel_2026[[#This Row],[Pontuação2]]>=5,"Próximo","Não"))) -> Sim | C13: =IFERROR(VLOOKUP(Rel_2026[[#This Row],[chave_loja]],Responsavel!A:B,2,FALSE),"EUCLIDES") -> JACK | D13: =LEFT(Rel_2026[[#This Row],[ag_pacb]],4) -> 0985 | E13: 424682 | F13: MERCEARIA CASA DO OVO | G13: 0985/455 | H13: 46185 | I13: PI | J13: CAMPO MAIOR | K13: 46182 | L13: 46205 | M13: TERESINA | N13: 46254 | O13: 116 | P13: 4 | Q13: 3 | R13: 4 | S13: 0 | T13: 0 | U13: 0 | V13: 0 | W13: 0 | X13: 0 | Y13: 0 | Z13: 0 | AA13: 0 | AB13: 0 | AC13: 0 | AD13: 0 | AE13: 0 | AF13: 4 | AG13: 0 | AH13: Nao | AI13: Desbloqueado | AK13: TREINADO | AL13: =IF(Rel_2026[[#This Row],[qtd_contas_com_deposito]]>0,7*Rel_2026[[#This Row],[qtd_contas_com_deposito]])+IF((Rel_2026[[#This Row],[qtd_contas]]-Rel_2026[[#This Row],[qtd_contas_com_deposito]])>0,(Rel_2026[[#This Row],[qtd_contas]]-Rel_2026[[#This Row],[qtd_contas_com_deposito]])*3)+IF(Rel_2026[[#This Row],[qtd_cesta_serv]]>0,0*Rel_2026[[#This Row],[qtd_cesta_serv]])+IF(Rel_2026[[#This Row],[QTD_CARTAO_EMITIDO]]>0,0*Rel_2026[[#This Row],[QTD_CARTAO_EMITIDO]])+IF(Rel_2026[[#This Row],[QTD_SUPER_PROTEGIDO]]>0,0*Rel_2026[[#This Row],[QTD_SUPER_PROTEGIDO]])+IF(Rel_2026[[#This Row],[QTD_CONTAS_PJ]]>0,0*Rel_2026[[#This Row],[QTD_CONTAS_PJ]])+IF(Rel_2026[[#This Row],[QTD_MICRO_VIVAVIDA]]>0,1*Rel_2026[[#This Row],[QTD_MICRO_VIVAVIDA]])+IF(Rel_2026[[#This Row],[qtd_microsseguro]]>0,1*Rel_2026[[#This Row],[qtd_microsseguro]])+IF(Rel_2026[[#This Row],[QTD_SEG_RESIDENCIAL]]>0,1*Rel_2026[[#This Row],[QTD_SEG_RESIDENCIAL]])+IF(Rel_2026[[#This Row],[QTD_PLANO_ODONTO]]>0,1*Rel_2026[[#This Row],[QTD_PLANO_ODONTO]])+IF(Rel_2026[[#This Row],[vlr_lime]]>0,1*ROUND(Rel_2026[[#This Row],[vlr_lime]]/100,0))+ROUND(IF(Rel_2026[[#This Row],[VLR_CREDITO_PARCEL]]>500,1*Rel_2026[[#This Row],[VLR_CREDITO_PARCEL]]/500),0)+ROUND(Rel_2026[[#This Row],[vlr_consignado_total]]/1000,0)+ROUND(Rel_2026[[#This Row],[VLR_EXP_SORTE]]/50,0) -> 24 | AM13: =SUM(Rel_2026[[#This Row],[qtd_TrxContabil]:[VLR_EXP_SORTE]]) -> 131 | AN13: =IF(Rel_2026[[#This Row],[qtd_contas_com_deposito]]>0,7*Rel_2026[[#This Row],[qtd_contas_com_deposito]])+IF((Rel_2026[[#This Row],[qtd_contas]]-Rel_2026[[#This Row],[qtd_contas_com_deposito]])>0,(Rel_2026[[#This Row],[qtd_contas]]-Rel_2026[[#This Row],[qtd_contas_com_deposito]])*3)+IF(Rel_2026[[#This Row],[qtd_cesta_serv]]>0,3*Rel_2026[[#This Row],[qtd_cesta_serv]])+IF(Rel_2026[[#This Row],[QTD_CARTAO_EMITIDO]]>0,0*Rel_2026[[#This Row],[QTD_CARTAO_EMITIDO]])+IF(Rel_2026[[#This Row],[QTD_SUPER_PROTEGIDO]]>0,0*Rel_2026[[#This Row],[QTD_SUPER_PROTEGIDO]])+IF(Rel_2026[[#This Row],[QTD_CONTAS_PJ]]>0,0*Rel_2026[[#This Row],[QTD_CONTAS_PJ]])+IF(Rel_2026[[#This Row],[QTD_MICRO_VIVAVIDA]]>0,1*Rel_2026[[#This Row],[QTD_MICRO_VIVAVIDA]])+IF(Rel_2026[[#This Row],[qtd_microsseguro]]>0,1*Rel_2026[[#This Row],[qtd_microsseguro]])+IF(Rel_2026[[#This Row],[QTD_SEG_RESIDENCIAL]]>0,1*Rel_2026[[#This Row],[QTD_SEG_RESIDENCIAL]])+IF(Rel_2026[[#This Row],[QTD_PLANO_ODONTO]]>0,1*Rel_2026[[#This Row],[QTD_PLANO_ODONTO]])+IF(Rel_2026[[#This Row],[vlr_lime]]>0,1*ROUND(Rel_2026[[#This Row],[vlr_lime]]/100,0))+ROUND(IF(Rel_2026[[#This Row],[VLR_CREDITO_PARCEL]]>500,1*Rel_2026[[#This Row],[VLR_CREDITO_PARCEL]]/500),0)+ROUND(Rel_2026[[#This Row],[vlr_consignado_total]]/1000,0)+ROUND(Rel_2026[[#This Row],[VLR_EXP_SORTE]]/50,0) -> 36
A14: =IF(Rel_2026[[#This Row],[Zero]]=0,"Zero",IF(Rel_2026[[#This Row],[Pontuação]]>=10,"Sim",IF(Rel_2026[[#This Row],[Pontuação]]>=5,"Próximo","Não"))) -> Não | B14: =IF(Rel_2026[[#This Row],[Zero]]=0,"Zero",IF(Rel_2026[[#This Row],[Pontuação2]]>=10,"Sim",IF(Rel_2026[[#This Row],[Pontuação2]]>=5,"Próximo","Não"))) -> Não | C14: =IFERROR(VLOOKUP(Rel_2026[[#This Row],[chave_loja]],Responsavel!A:B,2,FALSE),"EUCLIDES") -> ISMAEL | D14: =LEFT(Rel_2026[[#This Row],[ag_pacb]],4) -> 1302 | E14: 150023 | F14: SUPER POVAO 0001 | G14: 1302/119 | H14: 45155 | I14: CE | J14: ITATIRA | K14: 42551 | L14: 46227 | M14: FORTALEZA OESTE | N14: 46254 | O14: 617 | P14: 1 | Q14: 0 | R14: 0 | S14: 0 | T14: 0 | U14: 0 | V14: 0 | W14: 0 | X14: 0 | Y14: 0 | Z14: 0 | AA14: 0 | AB14: 0 | AC14: 0 | AD14: 0 | AE14: 0 | AF14: 1 | AG14: 0 | AH14: Nao | AI14: Desbloqueado | AK14: TREINADO | AL14: =IF(Rel_2026[[#This Row],[qtd_contas_com_deposito]]>0,7*Rel_2026[[#This Row],[qtd_contas_com_deposito]])+IF((Rel_2026[[#This Row],[qtd_contas]]-Rel_2026[[#This Row],[qtd_contas_com_deposito]])>0,(Rel_2026[[#This Row],[qtd_contas]]-Rel_2026[[#This Row],[qtd_contas_com_deposito]])*3)+IF(Rel_2026[[#This Row],[qtd_cesta_serv]]>0,0*Rel_2026[[#This Row],[qtd_cesta_serv]])+IF(Rel_2026[[#This Row],[QTD_CARTAO_EMITIDO]]>0,0*Rel_2026[[#This Row],[QTD_CARTAO_EMITIDO]])+IF(Rel_2026[[#This Row],[QTD_SUPER_PROTEGIDO]]>0,0*Rel_2026[[#This Row],[QTD_SUPER_PROTEGIDO]])+IF(Rel_2026[[#This Row],[QTD_CONTAS_PJ]]>0,0*Rel_2026[[#This Row],[QTD_CONTAS_PJ]])+IF(Rel_2026[[#This Row],[QTD_MICRO_VIVAVIDA]]>0,1*Rel_2026[[#This Row],[QTD_MICRO_VIVAVIDA]])+IF(Rel_2026[[#This Row],[qtd_microsseguro]]>0,1*Rel_2026[[#This Row],[qtd_microsseguro]])+IF(Rel_2026[[#This Row],[QTD_SEG_RESIDENCIAL]]>0,1*Rel_2026[[#This Row],[QTD_SEG_RESIDENCIAL]])+IF(Rel_2026[[#This Row],[QTD_PLANO_ODONTO]]>0,1*Rel_2026[[#This Row],[QTD_PLANO_ODONTO]])+IF(Rel_2026[[#This Row],[vlr_lime]]>0,1*ROUND(Rel_2026[[#This Row],[vlr_lime]]/100,0))+ROUND(IF(Rel_2026[[#This Row],[VLR_CREDITO_PARCEL]]>500,1*Rel_2026[[#This Row],[VLR_CREDITO_PARCEL]]/500),0)+ROUND(Rel_2026[[#This Row],[vlr_consignado_total]]/1000,0)+ROUND(Rel_2026[[#This Row],[VLR_EXP_SORTE]]/50,0) -> 3 | AM14: =SUM(Rel_2026[[#This Row],[qtd_TrxContabil]:[VLR_EXP_SORTE]]) -> 619 | AN14: =IF(Rel_2026[[#This Row],[qtd_contas_com_deposito]]>0,7*Rel_2026[[#This Row],[qtd_contas_com_deposito]])+IF((Rel_2026[[#This Row],[qtd_contas]]-Rel_2026[[#This Row],[qtd_contas_com_deposito]])>0,(Rel_2026[[#This Row],[qtd_contas]]-Rel_2026[[#This Row],[qtd_contas_com_deposito]])*3)+IF(Rel_2026[[#This Row],[qtd_cesta_serv]]>0,3*Rel_2026[[#This Row],[qtd_cesta_serv]])+IF(Rel_2026[[#This Row],[QTD_CARTAO_EMITIDO]]>0,0*Rel_2026[[#This Row],[QTD_CARTAO_EMITIDO]])+IF(Rel_2026[[#This Row],[QTD_SUPER_PROTEGIDO]]>0,0*Rel_2026[[#This Row],[QTD_SUPER_PROTEGIDO]])+IF(Rel_2026[[#This Row],[QTD_CONTAS_PJ]]>0,0*Rel_2026[[#This Row],[QTD_CONTAS_PJ]])+IF(Rel_2026[[#This Row],[QTD_MICRO_VIVAVIDA]]>0,1*Rel_2026[[#This Row],[QTD_MICRO_VIVAVIDA]])+IF(Rel_2026[[#This Row],[qtd_microsseguro]]>0,1*Rel_2026[[#This Row],[qtd_microsseguro]])+IF(Rel_2026[[#This Row],[QTD_SEG_RESIDENCIAL]]>0,1*Rel_2026[[#This Row],[QTD_SEG_RESIDENCIAL]])+IF(Rel_2026[[#This Row],[QTD_PLANO_ODONTO]]>0,1*Rel_2026[[#This Row],[QTD_PLANO_ODONTO]])+IF(Rel_2026[[#This Row],[vlr_lime]]>0,1*ROUND(Rel_2026[[#This Row],[vlr_lime]]/100,0))+ROUND(IF(Rel_2026[[#This Row],[VLR_CREDITO_PARCEL]]>500,1*Rel_2026[[#This Row],[VLR_CREDITO_PARCEL]]/500),0)+ROUND(Rel_2026[[#This Row],[vlr_consignado_total]]/1000,0)+ROUND(Rel_2026[[#This Row],[VLR_EXP_SORTE]]/50,0) -> 3
A15: =IF(Rel_2026[[#This Row],[Zero]]=0,"Zero",IF(Rel_2026[[#This Row],[Pontuação]]>=10,"Sim",IF(Rel_2026[[#This Row],[Pontuação]]>=5,"Próximo","Não"))) -> Não | B15: =IF(Rel_2026[[#This Row],[Zero]]=0,"Zero",IF(Rel_2026[[#This Row],[Pontuação2]]>=10,"Sim",IF(Rel_2026[[#This Row],[Pontuação2]]>=5,"Próximo","Não"))) -> Não | C15: =IFERROR(VLOOKUP(Rel_2026[[#This Row],[chave_loja]],Responsavel!A:B,2,FALSE),"EUCLIDES") -> NYCOLLAS | D15: =LEFT(Rel_2026[[#This Row],[ag_pacb]],4) -> 0719 | E15: 201292 | F15: BOMBONIERE RENAN E MYLA | G15: 0719/140 | H15: 44365 | I15: CE | J15: IRAUCUBA | K15: 44469 | L15: 45911 | M15: FORTALEZA OESTE | N15: 46254 | O15: 587 | P15: 0 | Q15: 0 | R15: 0 | S15: 0 | T15: 0 | U15: 0 | V15: 0 | W15: 0 | X15: 0 | Y15: 0 | Z15: 0 | AA15: 0 | AB15: 0 | AC15: 0 | AD15: 0 | AE15: 0 | AF15: 0 | AG15: 0 | AH15: Sim | AI15: Desbloqueado | AK15: TREINADO | AL15: =IF(Rel_2026[[#This Row],[qtd_contas_com_deposito]]>0,7*Rel_2026[[#This Row],[qtd_contas_com_deposito]])+IF((Rel_2026[[#This Row],[qtd_contas]]-Rel_2026[[#This Row],[qtd_contas_com_deposito]])>0,(Rel_2026[[#This Row],[qtd_contas]]-Rel_2026[[#This Row],[qtd_contas_com_deposito]])*3)+IF(Rel_2026[[#This Row],[qtd_cesta_serv]]>0,0*Rel_2026[[#This Row],[qtd_cesta_serv]])+IF(Rel_2026[[#This Row],[QTD_CARTAO_EMITIDO]]>0,0*Rel_2026[[#This Row],[QTD_CARTAO_EMITIDO]])+IF(Rel_2026[[#This Row],[QTD_SUPER_PROTEGIDO]]>0,0*Rel_2026[[#This Row],[QTD_SUPER_PROTEGIDO]])+IF(Rel_2026[[#This Row],[QTD_CONTAS_PJ]]>0,0*Rel_2026[[#This Row],[QTD_CONTAS_PJ]])+IF(Rel_2026[[#This Row],[QTD_MICRO_VIVAVIDA]]>0,1*Rel_2026[[#This Row],[QTD_MICRO_VIVAVIDA]])+IF(Rel_2026[[#This Row],[qtd_microsseguro]]>0,1*Rel_2026[[#This Row],[qtd_microsseguro]])+IF(Rel_2026[[#This Row],[QTD_SEG_RESIDENCIAL]]>0,1*Rel_2026[[#This Row],[QTD_SEG_RESIDENCIAL]])+IF(Rel_2026[[#This Row],[QTD_PLANO_ODONTO]]>0,1*Rel_2026[[#This Row],[QTD_PLANO_ODONTO]])+IF(Rel_2026[[#This Row],[vlr_lime]]>0,1*ROUND(Rel_2026[[#This Row],[vlr_lime]]/100,0))+ROUND(IF(Rel_2026[[#This Row],[VLR_CREDITO_PARCEL]]>500,1*Rel_2026[[#This Row],[VLR_CREDITO_PARCEL]]/500),0)+ROUND(Rel_2026[[#This Row],[vlr_consignado_total]]/1000,0)+ROUND(Rel_2026[[#This Row],[VLR_EXP_SORTE]]/50,0) -> 0 | AM15: =SUM(Rel_2026[[#This Row],[qtd_TrxContabil]:[VLR_EXP_SORTE]]) -> 587 | AN15: =IF(Rel_2026[[#This Row],[qtd_contas_com_deposito]]>0,7*Rel_2026[[#This Row],[qtd_contas_com_deposito]])+IF((Rel_2026[[#This Row],[qtd_contas]]-Rel_2026[[#This Row],[qtd_contas_com_deposito]])>0,(Rel_2026[[#This Row],[qtd_contas]]-Rel_2026[[#This Row],[qtd_contas_com_deposito]])*3)+IF(Rel_2026[[#This Row],[qtd_cesta_serv]]>0,3*Rel_2026[[#This Row],[qtd_cesta_serv]])+IF(Rel_2026[[#This Row],[QTD_CARTAO_EMITIDO]]>0,0*Rel_2026[[#This Row],[QTD_CARTAO_EMITIDO]])+IF(Rel_2026[[#This Row],[QTD_SUPER_PROTEGIDO]]>0,0*Rel_2026[[#This Row],[QTD_SUPER_PROTEGIDO]])+IF(Rel_2026[[#This Row],[QTD_CONTAS_PJ]]>0,0*Rel_2026[[#This Row],[QTD_CONTAS_PJ]])+IF(Rel_2026[[#This Row],[QTD_MICRO_VIVAVIDA]]>0,1*Rel_2026[[#This Row],[QTD_MICRO_VIVAVIDA]])+IF(Rel_2026[[#This Row],[qtd_microsseguro]]>0,1*Rel_2026[[#This Row],[qtd_microsseguro]])+IF(Rel_2026[[#This Row],[QTD_SEG_RESIDENCIAL]]>0,1*Rel_2026[[#This Row],[QTD_SEG_RESIDENCIAL]])+IF(Rel_2026[[#This Row],[QTD_PLANO_ODONTO]]>0,1*Rel_2026[[#This Row],[QTD_PLANO_ODONTO]])+IF(Rel_2026[[#This Row],[vlr_lime]]>0,1*ROUND(Rel_2026[[#This Row],[vlr_lime]]/100,0))+ROUND(IF(Rel_2026[[#This Row],[VLR_CREDITO_PARCEL]]>500,1*Rel_2026[[#This Row],[VLR_CREDITO_PARCEL]]/500),0)+ROUND(Rel_2026[[#This Row],[vlr_consignado_total]]/1000,0)+ROUND(Rel_2026[[#This Row],[VLR_EXP_SORTE]]/50,0) -> 0
A16: =IF(Rel_2026[[#This Row],[Zero]]=0,"Zero",IF(Rel_2026[[#This Row],[Pontuação]]>=10,"Sim",IF(Rel_2026[[#This Row],[Pontuação]]>=5,"Próximo","Não"))) -> Não | B16: =IF(Rel_2026[[#This Row],[Zero]]=0,"Zero",IF(Rel_2026[[#This Row],[Pontuação2]]>=10,"Sim",IF(Rel_2026[[#This Row],[Pontuação2]]>=5,"Próximo","Não"))) -> Não | C16: =IFERROR(VLOOKUP(Rel_2026[[#This Row],[chave_loja]],Responsavel!A:B,2,FALSE),"EUCLIDES") -> ROSSY | D16: =LEFT(Rel_2026[[#This Row],[ag_pacb]],4) -> 5792 | E16: 403204 | F16: Drogaria Maanaim | G16: 5792/193 | H16: 45450 | I16: PI | J16: BARRAS | K16: 45429 | L16: 45454 | M16: TERESINA | N16: 46254 | O16: 739 | P16: 0 | Q16: 0 | R16: 0 | S16: 0 | T16: 0 | U16: 0 | V16: 0 | W16: 0 | X16: 0 | Y16: 0 | Z16: 0 | AA16: 0 | AB16: 0 | AC16: 0 | AD16: 0 | AE16: 0 | AF16: 0 | AG16: 0 | AH16: Nao | AI16: Desbloqueado | AK16: TREINADO | AL16: =IF(Rel_2026[[#This Row],[qtd_contas_com_deposito]]>0,7*Rel_2026[[#This Row],[qtd_contas_com_deposito]])+IF((Rel_2026[[#This Row],[qtd_contas]]-Rel_2026[[#This Row],[qtd_contas_com_deposito]])>0,(Rel_2026[[#This Row],[qtd_contas]]-Rel_2026[[#This Row],[qtd_contas_com_deposito]])*3)+IF(Rel_2026[[#This Row],[qtd_cesta_serv]]>0,0*Rel_2026[[#This Row],[qtd_cesta_serv]])+IF(Rel_2026[[#This Row],[QTD_CARTAO_EMITIDO]]>0,0*Rel_2026[[#This Row],[QTD_CARTAO_EMITIDO]])+IF(Rel_2026[[#This Row],[QTD_SUPER_PROTEGIDO]]>0,0*Rel_2026[[#This Row],[QTD_SUPER_PROTEGIDO]])+IF(Rel_2026[[#This Row],[QTD_CONTAS_PJ]]>0,0*Rel_2026[[#This Row],[QTD_CONTAS_PJ]])+IF(Rel_2026[[#This Row],[QTD_MICRO_VIVAVIDA]]>0,1*Rel_2026[[#This Row],[QTD_MICRO_VIVAVIDA]])+IF(Rel_2026[[#This Row],[qtd_microsseguro]]>0,1*Rel_2026[[#This Row],[qtd_microsseguro]])+IF(Rel_2026[[#This Row],[QTD_SEG_RESIDENCIAL]]>0,1*Rel_2026[[#This Row],[QTD_SEG_RESIDENCIAL]])+IF(Rel_2026[[#This Row],[QTD_PLANO_ODONTO]]>0,1*Rel_2026[[#This Row],[QTD_PLANO_ODONTO]])+IF(Rel_2026[[#This Row],[vlr_lime]]>0,1*ROUND(Rel_2026[[#This Row],[vlr_lime]]/100,0))+ROUND(IF(Rel_2026[[#This Row],[VLR_CREDITO_PARCEL]]>500,1*Rel_2026[[#This Row],[VLR_CREDITO_PARCEL]]/500),0)+ROUND(Rel_2026[[#This Row],[vlr_consignado_total]]/1000,0)+ROUND(Rel_2026[[#This Row],[VLR_EXP_SORTE]]/50,0) -> 0 | AM16: =SUM(Rel_2026[[#This Row],[qtd_TrxContabil]:[VLR_EXP_SORTE]]) -> 739 | AN16: =IF(Rel_2026[[#This Row],[qtd_contas_com_deposito]]>0,7*Rel_2026[[#This Row],[qtd_contas_com_deposito]])+IF((Rel_2026[[#This Row],[qtd_contas]]-Rel_2026[[#This Row],[qtd_contas_com_deposito]])>0,(Rel_2026[[#This Row],[qtd_contas]]-Rel_2026[[#This Row],[qtd_contas_com_deposito]])*3)+IF(Rel_2026[[#This Row],[qtd_cesta_serv]]>0,3*Rel_2026[[#This Row],[qtd_cesta_serv]])+IF(Rel_2026[[#This Row],[QTD_CARTAO_EMITIDO]]>0,0*Rel_2026[[#This Row],[QTD_CARTAO_EMITIDO]])+IF(Rel_2026[[#This Row],[QTD_SUPER_PROTEGIDO]]>0,0*Rel_2026[[#This Row],[QTD_SUPER_PROTEGIDO]])+IF(Rel_2026[[#This Row],[QTD_CONTAS_PJ]]>0,0*Rel_2026[[#This Row],[QTD_CONTAS_PJ]])+IF(Rel_2026[[#This Row],[QTD_MICRO_VIVAVIDA]]>0,1*Rel_2026[[#This Row],[QTD_MICRO_VIVAVIDA]])+IF(Rel_2026[[#This Row],[qtd_microsseguro]]>0,1*Rel_2026[[#This Row],[qtd_microsseguro]])+IF(Rel_2026[[#This Row],[QTD_SEG_RESIDENCIAL]]>0,1*Rel_2026[[#This Row],[QTD_SEG_RESIDENCIAL]])+IF(Rel_2026[[#This Row],[QTD_PLANO_ODONTO]]>0,1*Rel_2026[[#This Row],[QTD_PLANO_ODONTO]])+IF(Rel_2026[[#This Row],[vlr_lime]]>0,1*ROUND(Rel_2026[[#This Row],[vlr_lime]]/100,0))+ROUND(IF(Rel_2026[[#This Row],[VLR_CREDITO_PARCEL]]>500,1*Rel_2026[[#This Row],[VLR_CREDITO_PARCEL]]/500),0)+ROUND(Rel_2026[[#This Row],[vlr_consignado_total]]/1000,0)+ROUND(Rel_2026[[#This Row],[VLR_EXP_SORTE]]/50,0) -> 0
A17: =IF(Rel_2026[[#This Row],[Zero]]=0,"Zero",IF(Rel_2026[[#This Row],[Pontuação]]>=10,"Sim",IF(Rel_2026[[#This Row],[Pontuação]]>=5,"Próximo","Não"))) -> Não | B17: =IF(Rel_2026[[#This Row],[Zero]]=0,"Zero",IF(Rel_2026[[#This Row],[Pontuação2]]>=10,"Sim",IF(Rel_2026[[#This Row],[Pontuação2]]>=5,"Próximo","Não"))) -> Não | C17: =IFERROR(VLOOKUP(Rel_2026[[#This Row],[chave_loja]],Responsavel!A:B,2,FALSE),"EUCLIDES") -> ISMAEL | D17: =LEFT(Rel_2026[[#This Row],[ag_pacb]],4) -> 0704 | E17: 423957 | F17: Mercadinho Zé Hugo | G17: 0704/191 | H17: 46148 | I17: CE | J17: ARACOIABA | K17: 46146 | L17: 46161 | M17: FORTALEZA LESTE | N17: 46254 | O17: 188 | P17: 0 | Q17: 0 | R17: 0 | S17: 0 | T17: 0 | U17: 0 | V17: 0 | W17: 0 | X17: 0 | Y17: 0 | Z17: 0 | AA17: 0 | AB17: 0 | AC17: 0 | AD17: 0 | AE17: 0 | AF17: 0 | AG17: 40 | AH17: Nao | AI17: Desbloqueado | AK17: TREINADO | AL17: =IF(Rel_2026[[#This Row],[qtd_contas_com_deposito]]>0,7*Rel_2026[[#This Row],[qtd_contas_com_deposito]])+IF((Rel_2026[[#This Row],[qtd_contas]]-Rel_2026[[#This Row],[qtd_contas_com_deposito]])>0,(Rel_2026[[#This Row],[qtd_contas]]-Rel_2026[[#This Row],[qtd_contas_com_deposito]])*3)+IF(Rel_2026[[#This Row],[qtd_cesta_serv]]>0,0*Rel_2026[[#This Row],[qtd_cesta_serv]])+IF(Rel_2026[[#This Row],[QTD_CARTAO_EMITIDO]]>0,0*Rel_2026[[#This Row],[QTD_CARTAO_EMITIDO]])+IF(Rel_2026[[#This Row],[QTD_SUPER_PROTEGIDO]]>0,0*Rel_2026[[#This Row],[QTD_SUPER_PROTEGIDO]])+IF(Rel_2026[[#This Row],[QTD_CONTAS_PJ]]>0,0*Rel_2026[[#This Row],[QTD_CONTAS_PJ]])+IF(Rel_2026[[#This Row],[QTD_MICRO_VIVAVIDA]]>0,1*Rel_2026[[#This Row],[QTD_MICRO_VIVAVIDA]])+IF(Rel_2026[[#This Row],[qtd_microsseguro]]>0,1*Rel_2026[[#This Row],[qtd_microsseguro]])+IF(Rel_2026[[#This Row],[QTD_SEG_RESIDENCIAL]]>0,1*Rel_2026[[#This Row],[QTD_SEG_RESIDENCIAL]])+IF(Rel_2026[[#This Row],[QTD_PLANO_ODONTO]]>0,1*Rel_2026[[#This Row],[QTD_PLANO_ODONTO]])+IF(Rel_2026[[#This Row],[vlr_lime]]>0,1*ROUND(Rel_2026[[#This Row],[vlr_lime]]/100,0))+ROUND(IF(Rel_2026[[#This Row],[VLR_CREDITO_PARCEL]]>500,1*Rel_2026[[#This Row],[VLR_CREDITO_PARCEL]]/500),0)+ROUND(Rel_2026[[#This Row],[vlr_consignado_total]]/1000,0)+ROUND(Rel_2026[[#This Row],[VLR_EXP_SORTE]]/50,0) -> 1 | AM17: =SUM(Rel_2026[[#This Row],[qtd_TrxContabil]:[VLR_EXP_SORTE]]) -> 228 | AN17: =IF(Rel_2026[[#This Row],[qtd_contas_com_deposito]]>0,7*Rel_2026[[#This Row],[qtd_contas_com_deposito]])+IF((Rel_2026[[#This Row],[qtd_contas]]-Rel_2026[[#This Row],[qtd_contas_com_deposito]])>0,(Rel_2026[[#This Row],[qtd_contas]]-Rel_2026[[#This Row],[qtd_contas_com_deposito]])*3)+IF(Rel_2026[[#This Row],[qtd_cesta_serv]]>0,3*Rel_2026[[#This Row],[qtd_cesta_serv]])+IF(Rel_2026[[#This Row],[QTD_CARTAO_EMITIDO]]>0,0*Rel_2026[[#This Row],[QTD_CARTAO_EMITIDO]])+IF(Rel_2026[[#This Row],[QTD_SUPER_PROTEGIDO]]>0,0*Rel_2026[[#This Row],[QTD_SUPER_PROTEGIDO]])+IF(Rel_2026[[#This Row],[QTD_CONTAS_PJ]]>0,0*Rel_2026[[#This Row],[QTD_CONTAS_PJ]])+IF(Rel_2026[[#This Row],[QTD_MICRO_VIVAVIDA]]>0,1*Rel_2026[[#This Row],[QTD_MICRO_VIVAVIDA]])+IF(Rel_2026[[#This Row],[qtd_microsseguro]]>0,1*Rel_2026[[#This Row],[qtd_microsseguro]])+IF(Rel_2026[[#This Row],[QTD_SEG_RESIDENCIAL]]>0,1*Rel_2026[[#This Row],[QTD_SEG_RESIDENCIAL]])+IF(Rel_2026[[#This Row],[QTD_PLANO_ODONTO]]>0,1*Rel_2026[[#This Row],[QTD_PLANO_ODONTO]])+IF(Rel_2026[[#This Row],[vlr_lime]]>0,1*ROUND(Rel_2026[[#This Row],[vlr_lime]]/100,0))+ROUND(IF(Rel_2026[[#This Row],[VLR_CREDITO_PARCEL]]>500,1*Rel_2026[[#This Row],[VLR_CREDITO_PARCEL]]/500),0)+ROUND(Rel_2026[[#This Row],[vlr_consignado_total]]/1000,0)+ROUND(Rel_2026[[#This Row],[VLR_EXP_SORTE]]/50,0) -> 1
